<robot name = "robot">
    <link name="Torso">
        <inertial>
            <origin xyz="0 0 1" rpy="0 0 0"/>
            <mass value="3" />
            <inertia ixx="100" ixy="0" ixz="0" iyy="100" iyz="0" izz="100" />
        </inertial>
        <visual>
            <origin xyz="0 0 1" rpy="0 0 0"/>
            <geometry>
                <box size="1 1 1" />
            </geometry>
            <material name="Cyan">
                <color rgba="0 1 1 1"/>
            </material>
        </visual>
        <collision>
            <origin xyz="0 0 1" rpy="0 0 0"/>
            <geometry>
                <box size="1 1 1" />
            </geometry>
        </collision>
    </link>
    <joint name="Torso_BackLegRot" type="continuous">
       <parent link="Torso"/>
       <child  link="BackLegRot"/>
       <origin rpy="0 0 0" xyz="0 -0.5 1.0" />
     <axis xyz="0 1 0"/>
       
    </joint>
    <joint name="BackLegRot_BackLeg" type="continuous">
       <parent link="BackLegRot"/>
       <child  link="BackLeg"/>
       <origin rpy="0 0 0" xyz="0 0 0" />
     <axis xyz="1 0 0"/>
       
    </joint>
    <link name="BackLegRot">
        <inertial>
            <origin xyz="0.0 -0.5 0.0" rpy="0 0 0"/>
            <mass value="0.0" />
            <inertia ixx="100" ixy="0" ixz="0" iyy="100" iyz="0" izz="100" />
        </inertial>
        <visual>
            <origin xyz="0.0 -0.5 0.0" rpy="0 0 0"/>
            <geometry>
                <box size="0 0 0" />
            </geometry>
            <material name="Cyan">
                <color rgba="0 1 1 1"/>
            </material>
        </visual>
        <collision>
            <origin xyz="0.0 -0.5 0.0" rpy="0 0 0"/>
            <geometry>
                <box size="0 0 0" />
            </geometry>
        </collision>
    </link>
    <link name="BackLeg">
        <inertial>
            <origin xyz="0.0 -0.5 0.0" rpy="0 0 0"/>
            <mass value="1.0" />
            <inertia ixx="100" ixy="0" ixz="0" iyy="100" iyz="0" izz="100" />
        </inertial>
        <visual>
            <origin xyz="0.0 -0.5 0.0" rpy="0 0 0"/>
            <geometry>
                <box size="0.2 1.0 0.2" />
            </geometry>
            <material name="Cyan">
                <color rgba="0 1 1 1"/>
            </material>
        </visual>
        <collision>
            <origin xyz="0.0 -0.5 0.0" rpy="0 0 0"/>
            <geometry>
                <box size="0.2 1.0 0.2" />
            </geometry>
        </collision>
    </link>
    <joint name="Torso_FrontLegRot" type="continuous">
       <parent link="Torso"/>
       <child  link="FrontLegRot"/>
       <origin rpy="0 0 0" xyz="0.0 0.5 1.0" />
     <axis xyz="1 0 0"/>
       
    </joint>
    <joint name="FrontLegRot_FrontLeg" type="continuous">
       <parent link="FrontLegRot"/>
       <child  link="FrontLeg"/>
       <origin rpy="0 0 0" xyz="0.0 0.0 0.0" />
     <axis xyz="0 1 0"/>
       
    </joint>
    <link name="FrontLegRot">
        <inertial>
            <origin xyz="0.0 0.5 0" rpy="0 0 0"/>
            <mass value="0.0" />
            <inertia ixx="100" ixy="0" ixz="0" iyy="100" iyz="0" izz="100" />
        </inertial>
        <visual>
            <origin xyz="0.0 0.5 0" rpy="0 0 0"/>
            <geometry>
                <box size="0 0 0" />
            </geometry>
            <material name="Cyan">
                <color rgba="0 1 1 1"/>
            </material>
        </visual>
        <collision>
            <origin xyz="0.0 0.5 0" rpy="0 0 0"/>
            <geometry>
                <box size="0 0 0" />
            </geometry>
        </collision>
    </link>
    <link name="FrontLeg">
        <inertial>
            <origin xyz="0.0 0.5 0" rpy="0 0 0"/>
            <mass value="1.0" />
            <inertia ixx="100" ixy="0" ixz="0" iyy="100" iyz="0" izz="100" />
        </inertial>
        <visual>
            <origin xyz="0.0 0.5 0" rpy="0 0 0"/>
            <geometry>
                <box size="0.2 1.0 0.2" />
            </geometry>
            <material name="Cyan">
                <color rgba="0 1 1 1"/>
            </material>
        </visual>
        <collision>
            <origin xyz="0.0 0.5 0" rpy="0 0 0"/>
            <geometry>
                <box size="0.2 1.0 0.2" />
            </geometry>
        </collision>
    </link>
    <link name="LeftLeg">
        <inertial>
            <origin xyz="-0.5 0.0 0.0" rpy="0 0 0"/>
            <mass value="1.0" />
            <inertia ixx="100" ixy="0" ixz="0" iyy="100" iyz="0" izz="100" />
        </inertial>
        <visual>
            <origin xyz="-0.5 0.0 0.0" rpy="0 0 0"/>
            <geometry>
                <box size="1.0 0.2 0.2" />
            </geometry>
            <material name="Cyan">
                <color rgba="0 1 1 1"/>
            </material>
        </visual>
        <collision>
            <origin xyz="-0.5 0.0 0.0" rpy="0 0 0"/>
            <geometry>
                <box size="1.0 0.2 0.2" />
            </geometry>
        </collision>
    </link>
    <link name="LeftLegRot">
        <inertial>
            <origin xyz="-0.5 0.0 0.0" rpy="0 0 0"/>
            <mass value="0.0" />
            <inertia ixx="100" ixy="0" ixz="0" iyy="100" iyz="0" izz="100" />
        </inertial>
        <visual>
            <origin xyz="-0.5 0.0 0.0" rpy="0 0 0"/>
            <geometry>
                <box size="0 0 0" />
            </geometry>
            <material name="Cyan">
                <color rgba="0 1 1 1"/>
            </material>
        </visual>
        <collision>
            <origin xyz="-0.5 0.0 0.0" rpy="0 0 0"/>
            <geometry>
                <box size="0 0 0" />
            </geometry>
        </collision>
    </link>
    <joint name="Torso_LeftLegRot" type="continuous">
       <parent link="Torso"/>
       <child  link="LeftLegRot"/>
       <origin rpy="0 0 0" xyz="-0.5 0 1.0" />
     <axis xyz="1 0 0"/>
       
    </joint>
    <joint name="LeftLegRot_LeftLeg" type="continuous">
       <parent link="LeftLegRot"/>
       <child  link="LeftLeg"/>
       <origin rpy="0 0 0" xyz="0 0 0" />
     <axis xyz="0 1 0"/>
       
    </joint>
    <link name="RightLegRot">
        <inertial>
            <origin xyz="0.5 0.0 0.0" rpy="0 0 0"/>
            <mass value="0.0" />
            <inertia ixx="100" ixy="0" ixz="0" iyy="100" iyz="0" izz="100" />
        </inertial>
        <visual>
            <origin xyz="0.5 0.0 0.0" rpy="0 0 0"/>
            <geometry>
                <box size="0 0 0" />
            </geometry>
            <material name="Cyan">
                <color rgba="0 1 1 1"/>
            </material>
        </visual>
        <collision>
            <origin xyz="0.5 0.0 0.0" rpy="0 0 0"/>
            <geometry>
                <box size="0 0 0" />
            </geometry>
        </collision>
    </link>
    <link name="RightLeg">
        <inertial>
            <origin xyz="0.5 0.0 0.0" rpy="0 0 0"/>
            <mass value="1.0" />
            <inertia ixx="100" ixy="0" ixz="0" iyy="100" iyz="0" izz="100" />
        </inertial>
        <visual>
            <origin xyz="0.5 0.0 0.0" rpy="0 0 0"/>
            <geometry>
                <box size="1.0 0.2 0.2" />
            </geometry>
            <material name="Cyan">
                <color rgba="0 1 1 1"/>
            </material>
        </visual>
        <collision>
            <origin xyz="0.5 0.0 0.0" rpy="0 0 0"/>
            <geometry>
                <box size="1.0 0.2 0.2" />
            </geometry>
        </collision>
    </link>
    <joint name="Torso_RightLegRot" type="continuous">
       <parent link="Torso"/>
       <child  link="RightLegRot"/>
       <origin rpy="0 0 0" xyz="0.5 0 1.0" />
     <axis xyz="1 0 0"/>
       
    </joint>
    <joint name="RightLegRot_RightLeg" type="continuous">
       <parent link="RightLegRot"/>
       <child  link="RightLeg"/>
       <origin rpy="0 0 0" xyz="0 0 0" />
     <axis xyz="0 1 0"/>
       
    </joint>
    <link name="FrontLowerLeg">
        <inertial>
            <origin xyz="0.0 0.0 -0.5" rpy="0 0 0"/>
            <mass value="1.0" />
            <inertia ixx="100" ixy="0" ixz="0" iyy="100" iyz="0" izz="100" />
        </inertial>
        <visual>
            <origin xyz="0.0 0.0 -0.5" rpy="0 0 0"/>
            <geometry>
                <box size="0.2 0.2 1.0" />
            </geometry>
            <material name="Cyan">
                <color rgba="0 1 1 1"/>
            </material>
        </visual>
        <collision>
            <origin xyz="0.0 0.0 -0.5" rpy="0 0 0"/>
            <geometry>
                <box size="0.2 0.2 1.0" />
            </geometry>
        </collision>
    </link>
    <joint name="FrontLeg_FrontLowerLeg" type="continuous">
       <parent link="FrontLeg"/>
       <child  link="FrontLowerLeg"/>
       <origin rpy="0 0 0" xyz="0 1 0" />
     <axis xyz="1 0 0"/>
       
    </joint>
    <link name="BackLowerLeg">
        <inertial>
            <origin xyz="0.0 0.0 -0.5" rpy="0 0 0"/>
            <mass value="1.0" />
            <inertia ixx="100" ixy="0" ixz="0" iyy="100" iyz="0" izz="100" />
        </inertial>
        <visual>
            <origin xyz="0.0 0.0 -0.5" rpy="0 0 0"/>
            <geometry>
                <box size="0.2 0.2 1.0" />
            </geometry>
            <material name="Cyan">
                <color rgba="0 1 1 1"/>
            </material>
        </visual>
        <collision>
            <origin xyz="0.0 0.0 -0.5" rpy="0 0 0"/>
            <geometry>
                <box size="0.2 0.2 1.0" />
            </geometry>
        </collision>
    </link>
    <joint name="BackLeg_BackLowerLeg" type="continuous">
       <parent link="BackLeg"/>
       <child  link="BackLowerLeg"/>
       <origin rpy="0 0 0" xyz="0 -1 0" />
     <axis xyz="1 0 0"/>
       
    </joint>
    <link name="LeftLowerLeg">
        <inertial>
            <origin xyz="0.0 0.0 -0.5" rpy="0 0 0"/>
            <mass value="1.0" />
            <inertia ixx="100" ixy="0" ixz="0" iyy="100" iyz="0" izz="100" />
        </inertial>
        <visual>
            <origin xyz="0.0 0.0 -0.5" rpy="0 0 0"/>
            <geometry>
                <box size="0.2 0.2 1.0" />
            </geometry>
            <material name="Cyan">
                <color rgba="0 1 1 1"/>
            </material>
        </visual>
        <collision>
            <origin xyz="0.0 0.0 -0.5" rpy="0 0 0"/>
            <geometry>
                <box size="0.2 0.2 1.0" />
            </geometry>
        </collision>
    </link>
    <joint name="LeftLeg_LeftLowerLeg" type="continuous">
       <parent link="LeftLeg"/>
       <child  link="LeftLowerLeg"/>
       <origin rpy="0 0 0" xyz="-1 0 0" />
     <axis xyz="0 1 0"/>
       
    </joint>
    <link name="RightLowerLeg">
        <inertial>
            <origin xyz="0.0 0.0 -0.5" rpy="0 0 0"/>
            <mass value="1.0" />
            <inertia ixx="100" ixy="0" ixz="0" iyy="100" iyz="0" izz="100" />
        </inertial>
        <visual>
            <origin xyz="0.0 0.0 -0.5" rpy="0 0 0"/>
            <geometry>
                <box size="0.2 0.2 1.0" />
            </geometry>
            <material name="Cyan">
                <color rgba="0 1 1 1"/>
            </material>
        </visual>
        <collision>
            <origin xyz="0.0 0.0 -0.5" rpy="0 0 0"/>
            <geometry>
                <box size="0.2 0.2 1.0" />
            </geometry>
        </collision>
    </link>
    <joint name="RightLeg_RightLowerLeg" type="continuous">
       <parent link="RightLeg"/>
       <child  link="RightLowerLeg"/>
       <origin rpy="0 0 0" xyz="1 0 0" />
     <axis xyz="0 1 0"/>
       
    </joint>
</robot>